import { describe, it, expect, vi } from 'vitest';
import { render, screen } from '@testing-library/react';
import ErrorBoundary from '../components/ErrorBoundary';

// Mock component that throws an error
const ThrowError = ({ shouldThrow }: { shouldThrow: boolean }) => {
  if (shouldThrow) {
    throw new Error('Test error');
  }
  return <div>No error</div>;
};

// Mock the language context
vi.mock('../contexts/LanguageContext', () => ({
  useLanguage: () => ({
    language: 'en',
  }),
}));

describe('ErrorBoundary', () => {
  it('renders children when there is no error', () => {
    render(
      <ErrorBoundary>
        <ThrowError shouldThrow={false} />
      </ErrorBoundary>
    );

    expect(screen.getByText('No error')).toBeInTheDocument();
  });

  it('renders error fallback when there is an error', () => {
    // Suppress console.error for this test
    const consoleSpy = vi.spyOn(console, 'error').mockImplementation(() => {});

    render(
      <ErrorBoundary>
        <ThrowError shouldThrow={true} />
      </ErrorBoundary>
    );

    expect(screen.getByText('Something went wrong')).toBeInTheDocument();
    expect(screen.getByText('An unexpected error occurred. Please try again.')).toBeInTheDocument();

    consoleSpy.mockRestore();
  });

  it('shows retry and reload buttons', () => {
    const consoleSpy = vi.spyOn(console, 'error').mockImplementation(() => {});

    render(
      <ErrorBoundary>
        <ThrowError shouldThrow={true} />
      </ErrorBoundary>
    );

    expect(screen.getByText('Try Again')).toBeInTheDocument();
    expect(screen.getByText('Reload Page')).toBeInTheDocument();

    consoleSpy.mockRestore();
  });
});
